Workbook

Sheet discountedtwo
A1: id | B1: uuid | C1: barcode | D1: title | E1: description | F1: selling_price | G1: category_id | H1: sub_category | I1: mini_category | J1: brand_id | K1: product_type | L1: product_image | M1: product_image_1 | N1: product_image_2 | O1: product_image_3 | P1: product_image_4 | Q1: product_image_5 | R1: product_image_6 | S1: product_image_7 | T1: product_image_8 | U1: product_image_9 | V1: product_image_10 | W1: quantity | X1: active | Y1: meta_keywords | Z1: created_at | AA1: updated_at | AB1: discount_percentage | AC1: discount_start | AD1: discount_end
A2: 319 | B2: 75378257-0e97-44eb-b475-ef0d69bf2696 | C2: 6920250103143 | D2: ZF Candy Dog 22CM | E2: ZF Candy Dog 22CM | F2: 550 | G2: 6 | H2: 48 | I2: 171 | J2: 0 | K2: NULL | L2: 6920250103143.jpg | W2: 1500 | X2: 1 | Z2: 2025-06-26T13:32:00.99999999627470925 | AA2: 2025-06-26T13:32:00.99999999627470925 | AB2: 30 | AC2: 2026-01-01T23:59:58.00000016111880300 | AD2: 2026-01-31T23:59:58.99999976623803075
A3: 320 | B3: a10b8848-e1ed-4da5-8964-42e6c688ea71 | C3: 6920250103150 | D3: LY Rabbit 18CM | E3: LY Rabbit 18CM | F3: 420 | G3: 6 | H3: 48 | I3: 171 | J3: 0 | K3: NULL | L3: 6920250103150.jpg | W3: 1500 | X3: 1 | Z3: 2025-06-26T13:32:00.99999999627470925 | AA3: 2025-06-26T13:32:00.99999999627470925 | AB3: 29.76 | AC3: 2026-01-01T23:59:58.00000016111880300 | AD3: 2026-01-31T23:59:58.99999976623803075
A4: 321 | B4: f671fe1f-f152-4891-a171-db462e056966 | C4: 6920250103181 | D4: WJX Snapping Panda 30CM | E4: WJX Snapping Panda 30CM | F4: 520 | G4: 6 | H4: 48 | I4: 171 | J4: 0 | K4: NULL | L4: 6920250103181.jpg | M4: 6920250103181 B.jpg | W4: 1500 | X4: 1 | Z4: 2025-06-26T13:32:00.99999999627470925 | AA4: 2025-06-26T13:32:00.99999999627470925 | AB4: 29.81 | AC4: 2026-01-01T23:59:58.00000016111880300 | AD4: 2026-01-31T23:59:58.99999976623803075
A5: 322 | B5: 0310129a-fd9b-4123-9bc9-c64cb9185aef | C5: 6920250103358 | D5: DGM Boutique Penguin 24CM | E5: DGM Boutique Penguin 24CM | F5: 640 | G5: 6 | H5: 48 | I5: 171 | J5: 0 | K5: NULL | L5: 6920250103358.jpg | W5: 1500 | X5: 1 | Z5: 2025-06-26T13:32:00.99999999627470925 | AA5: 2025-06-26T13:32:00.99999999627470925 | AB5: 29.69 | AC5: 2026-01-01T23:59:58.00000016111880300 | AD5: 2026-01-31T23:59:58.99999976623803075
A6: 323 | B6: 2ff78d6f-0d54-4f91-8e4c-928661e11ff6 | C6: 6920250103396 | D6: XHG Colorful Bear 30CM | E6: XHG Colorful Bear 30CM | F6: 800 | G6: 6 | H6: 48 | I6: 171 | J6: 0 | K6: NULL | L6: 6920250103396.jpg | W6: 1500 | X6: 1 | Z6: 2025-06-26T13:32:00.99999999627470925 | AA6: 2025-06-26T13:32:00.99999999627470925 | AB6: 30 | AC6: 2026-01-01T23:59:58.00000016111880300 | AD6: 2026-01-31T23:59:58.99999976623803075
A7: 324 | B7: 5086adaa-68f6-4d62-91ad-3728e672aadd | C7: 6920250103419 | D7: WZQ Flower Sitting Bear 22CM | E7: WZQ Flower Sitting Bear 22CM | F7: 700 | G7: 6 | H7: 48 | I7: 171 | J7: 0 | K7: NULL | L7: 6920250103419.jpg | W7: 1500 | X7: 1 | Z7: 2025-06-26T13:32:00.99999999627470925 | AA7: 2025-06-26T13:32:00.99999999627470925 | AB7: 30 | AC7: 2026-01-01T23:59:58.00000016111880300 | AD7: 2026-01-31T23:59:58.99999976623803075
A8: 325 | B8: f52b0ac4-d798-434d-87f6-980e09ac24ab | C8: 6920250103532 | D8: WBL Curly Coated Bichon Frise 20CM | E8: WBL Curly Coated Bichon Frise 20CM | F8: 780 | G8: 6 | H8: 48 | I8: 171 | J8: 0 | K8: NULL | L8: 6920250103532.jpg | M8: 6920250103532B.jpg | W8: 1500 | X8: 1 | Z8: 2025-06-26T13:32:00.99999999627470925 | AA8: 2025-06-26T13:32:00.99999999627470925 | AB8: 30.13 | AC8: 2026-01-01T23:59:58.00000016111880300 | AD8: 2026-01-31T23:59:58.99999976623803075
A9: 379 | B9: 52e69488-4f45-41fe-bfe6-c657765573ca | C9: 6971082817432 | D9: Weibo color pencil 12 colors | E9: Weibo color pencil 12 colors | F9: 200 | G9: 7 | H9: 0 | I9: 0 | J9: 0 | K9: NULL | L9: 6971082817432.jpg | W9: 1500 | X9: 1 | Z9: 2025-06-26T13:32:00.99999999627470925 | AA9: 2025-06-26T13:32:00.99999999627470925 | AB9: 30.56 | AC9: 2026-01-01T23:59:58.00000016111880300 | AD9: 2026-01-31T23:59:58.99999976623803075
A10: 380 | B10: c63acf8c-b141-42f2-a432-0fbe2a474cf7 | C10: 6971082817449 | D10: Weibo color pencil 18 colors | E10: Weibo color pencil 18 colors | F10: 280 | G10: 7 | H10: 0 | I10: 0 | J10: 0 | K10: NULL | L10: 6971082817449.jpg | W10: 1500 | X10: 1 | Z10: 2025-06-26T13:32:00.99999999627470925 | AA10: 2025-06-26T13:32:00.99999999627470925 | AB10: 30.36 | AC10: 2026-01-01T23:59:58.00000016111880300 | AD10: 2026-01-31T23:59:58.99999976623803075
A11: 381 | B11: 99158d0a-d170-49b4-99f6-0481ee94396a | C11: 6971082817456 | D11: Weibo color pencil 24 colors | E11: Weibo color pencil 24 colors | F11: 360 | G11: 7 | H11: 0 | I11: 0 | J11: 0 | K11: NULL | L11: 6971082817456.jpg | W11: 1500 | X11: 1 | Z11: 2025-06-26T13:32:00.99999999627470925 | AA11: 2025-06-26T13:32:00.99999999627470925 | AB11: 30 | AC11: 2026-01-01T23:59:58.00000016111880300 | AD11: 2026-01-31T23:59:58.99999976623803075
A12: 391 | B12: 628198c3-4caa-4039-8f2a-62fe9ab5004b | C12: 6976693300076 | D12: Weibo 12 Colors Powder | E12: Weibo 12 Colors Powder | F12: 320 | G12: 7 | H12: 0 | I12: 0 | J12: 0 | K12: NULL | L12: 6976693300076.jpg | W12: 1500 | X12: 1 | Z12: 2025-06-26T13:32:00.99999999627470925 | AA12: 2025-06-26T13:32:00.99999999627470925 | AB12: 29.63 | AC12: 2026-01-01T23:59:58.00000016111880300 | AD12: 2026-01-31T23:59:58.99999976623803075
A13: 392 | B13: e0c7b03e-aac1-4ef5-b54f-6fac9451c4bc | C13: 6976693300090 | D13: Weibo 28 Colors pastels | E13: Weibo 28 Colors pastels | F13: 700 | G13: 7 | H13: 0 | I13: 0 | J13: 0 | K13: NULL | L13: 6976693300090.jpg | W13: 1500 | X13: 1 | Z13: 2025-06-26T13:32:00.99999999627470925 | AA13: 2025-06-26T13:32:00.99999999627470925 | AB13: 30 | AC13: 2026-01-01T23:59:58.00000016111880300 | AD13: 2026-01-31T23:59:58.99999976623803075
A14: 394 | B14: b309f00b-6b58-447e-9527-1228fec5e593 | C14: 6976693300700 | D14: B5 PP Spacer Book | E14: B5 PP Spacer Book | F14: 460 | G14: 7 | H14: 0 | I14: 0 | J14: 0 | K14: NULL | L14: 6976693300700.jpg | W14: 1500 | X14: 1 | Z14: 2025-06-26T13:32:00.99999999627470925 | AA14: 2025-06-26T13:32:00.99999999627470925 | AB14: 8.7 | AC14: 2026-01-01T23:59:58.00000016111880300 | AD14: 2026-01-31T23:59:58.99999976623803075
A15: 396 | B15: ff90e182-c31a-4702-b521-8aa5ce0a04b3 | C15: 6976693301615 | D15: Twill page front insert with pen holder triple information rack | E15: Twill page front insert with pen holder triple information rack | F15: 1110 | G15: 7 | H15: 0 | I15: 0 | J15: 0 | K15: NULL | L15: 6976693301615.jpg | W15: 1500 | X15: 1 | Z15: 2025-06-26T13:32:00.99999999627470925 | AA15: 2025-06-26T13:32:00.99999999627470925 | AB15: 30.18 | AC15: 2026-01-01T23:59:58.00000016111880300 | AD15: 2026-01-31T23:59:58.99999976623803075
A16: 397 | B16: 440d1f86-0caf-43bb-8873-4731c3d62724 | C16: 6976693301622 | D16: Twill page front insert with pen holder 4pcs | E16: Twill page front insert with pen holder 4pcs | F16: 1360 | G16: 7 | H16: 0 | I16: 0 | J16: 0 | K16: NULL | L16: 6976693301622.jpg | W16: 1500 | X16: 1 | Z16: 2025-06-26T13:32:00.99999999627470925 | AA16: 2025-06-26T13:32:00.99999999627470925 | AB16: 30.15 | AC16: 2026-01-01T23:59:58.00000016111880300 | AD16: 2026-01-31T23:59:58.99999976623803075
A17: 400 | B17: 1dc19953-10b1-45d7-85b2-484b90a775b5 | C17: 6976693304449 | D17: Transparent Fluorescent Eraser | E17: Transparent Fluorescent Eraser | F17: 40 | G17: 7 | H17: 0 | I17: 0 | J17: 0 | K17: NULL | L17: 6976693304449.jpg | M17: 6976693304449 B.jpg | W17: 1500 | X17: 1 | Z17: 2025-06-26T13:32:00.99999999627470925 | AA17: 2025-06-26T13:32:00.99999999627470925 | AB17: 25 | AC17: 2026-01-01T23:59:58.00000016111880300 | AD17: 2026-01-31T23:59:58.99999976623803075
A18: 401 | B18: 2156a52b-5ca1-429e-af0f-84cbdfe3aff4 | C18: 6976693305163 | D18: Square Pen Holder | E18: Square Pen Holder | F18: 220 | G18: 7 | H18: 0 | I18: 0 | J18: 0 | K18: NULL | L18: 6976693305163.jpg | W18: 1500 | X18: 1 | Z18: 2025-06-26T13:32:00.99999999627470925 | AA18: 2025-06-26T13:32:00.99999999627470925 | AB18: 31.58 | AC18: 2026-01-01T23:59:58.00000016111880300 | AD18: 2026-01-31T23:59:58.99999976623803075
A19: 402 | B19: 43ec6d18-9890-470a-be63-a0fe266b4048 | C19: 6976693305170 | D19: Round Pen Holder | E19: Round Pen Holder | F19: 220 | G19: 7 | H19: 0 | I19: 0 | J19: 0 | K19: NULL | L19: 6976693305170.jpg | M19: 6976693305170 B.jpg | W19: 1500 | X19: 1 | Z19: 2025-06-26T13:32:00.99999999627470925 | AA19: 2025-06-26T13:32:00.99999999627470925 | AB19: 31.58 | AC19: 2026-01-01T23:59:58.00000016111880300 | AD19: 2026-01-31T23:59:58.99999976623803075
A20: 404 | B20: bbf3925c-10f1-4aa8-a79c-93f0ae0f0036 | C20: 6976693307471 | D20: Weibo Sketchbook A4 40PG | E20: Weibo Sketchbook A4 40PG | F20: 480 | G20: 7 | H20: 0 | I20: 0 | J20: 0 | K20: NULL | L20: 6976693307471.jpg | W20: 1500 | X20: 1 | Z20: 2025-06-26T13:32:00.99999999627470925 | AA20: 2025-06-26T13:32:00.99999999627470925 | AB20: 30.21 | AC20: 2026-01-01T23:59:58.00000016111880300 | AD20: 2026-01-31T23:59:58.99999976623803075
A21: 405 | B21: 86d0734d-0e92-4445-88a7-439281361b66 | C21: 6976693308188 | D21: A4 Leather Book | E21: A4 Leather Book | F21: 1000 | G21: 7 | H21: 0 | I21: 0 | J21: 0 | K21: NULL | L21: 6976693308188.jpg | W21: 1500 | X21: 1 | Z21: 2025-06-26T13:32:00.99999999627470925 | AA21: 2025-06-26T13:32:00.99999999627470925 | AB21: 30 | AC21: 2026-01-01T23:59:58.00000016111880300 | AD21: 2026-01-31T23:59:58.99999976623803075
A22: 406 | B22: e753cf64-acc3-4750-8fbd-7cc3330b34c3 | C22: 6976693309246 | D22: A5 leather book | E22: A5 leather book | F22: 600 | G22: 7 | H22: 0 | I22: 0 | J22: 0 | K22: NULL | L22: 6976693309246.jpg | W22: 1500 | X22: 1 | Z22: 2025-06-26T13:32:00.99999999627470925 | AA22: 2025-06-26T13:32:00.99999999627470925 | AB22: 30.19 | AC22: 2026-01-01T23:59:58.00000016111880300 | AD22: 2026-01-31T23:59:58.99999976623803075
A23: 408 | B23: 9bd77a90-6e6e-409f-aafc-0818055d448f | C23: 6977272390051 | D23: Drawing Board | E23: Drawing Board | F23: 450 | G23: 7 | H23: 0 | I23: 0 | J23: 0 | K23: NULL | L23: 6977272390051.jpg | W23: 1500 | X23: 1 | Z23: 2025-06-26T13:32:00.99999999627470925 | AA23: 2025-06-26T13:32:00.99999999627470925 | AB23: 30 | AC23: 2026-01-01T23:59:58.00000016111880300 | AD23: 2026-01-31T23:59:58.99999976623803075
A24: 409 | B24: ef9d9df1-0706-4f7c-9084-f63da6d1e711 | C24: 6977272390068 | D24: Drawing board WB05075 | E24: Drawing board WB-05076 | F24: 650 | G24: 7 | H24: 0 | I24: 0 | J24: 0 | K24: NULL | L24: 6977272390068.jpg | W24: 1500 | X24: 1 | Z24: 2025-06-26T13:32:00.99999999627470925 | AA24: 2025-06-26T13:32:00.99999999627470925 | AB24: 30 | AC24: 2026-01-01T23:59:58.00000016111880300 | AD24: 2026-01-31T23:59:58.99999976623803075
A25: 410 | B25: b7adf1b4-4257-4a58-a006-607e638c1e82 | C25: 6977272392802 | D25: Unicorn Hexagonal Pencil Sharpener | E25: Unicorn Hexagonal Pencil Sharpener | F25: 150 | G25: 7 | H25: 0 | I25: 0 | J25: 0 | K25: NULL | L25: 6977272392802.jpg | W25: 1500 | X25: 1 | Z25: 2025-06-26T13:32:00.99999999627470925 | AA25: 2025-06-26T13:32:00.99999999627470925 | AB25: 30 | AC25: 2026-01-01T23:59:58.00000016111880300 | AD25: 2026-01-31T23:59:58.99999976623803075
A26: 1067 | B26: b46320b5-30a1-48bc-8a7b-8b60779fd3a5 | C26: 6977272392994 | D26: 8 LCD Writing Board | E26: 8.5 â”œÃ¢â•žÃ†â”œÃ¥Î“Ã‡Ã–â”œÃ¢Î“Ã‡Ãœâ”œÃ©â”¬Ã³â”œÃ¢â•žÃ†â”œÃ©â”¬Ã³â”œÃ¢â”¬Ã³â”œÃ³Î“Ã‡Ãœâ”¬Â¼â”œÃ â”¬Ã­â”œÃ¢Î“Ã‡Ãœâ”œÃ©â”¬Â¼â”œÃ¢â•žÃ†â”œÃ³Î“Ã©Â¼â”¼Ã­â”œÃ¢Î“Ã‡Ãœâ”œÃ©â”¬Â¥LCD Writing Board | F26: 500 | G26: 7 | H26: 0 | I26: 0 | J26: 0 | K26: NULL | L26: 8.5_ LCD Writing Board (box).jpg | M26: 8.5_ LCD Writing Board 1.jpg | N26: 8.5_ LCD Writing Board 2.jpg | W26: 1500 | X26: 1 | Z26: 2025-06-26T13:32:00.99999999627470925 | AA26: 2025-06-26T13:32:00.99999999627470925 | AB26: 30 | AC26: 2026-01-01T23:59:58.00000016111880300 | AD26: 2026-01-31T23:59:58.99999976623803075
A27: 1068 | B27: 6245975b-1b9e-40dd-ab12-9d5b5931f6f0 | C27: 6977272393007 | D27: 10 LCD Writing Board | E27: 10.5â”œÃ¢â•žÃ†â”œÃ¥Î“Ã‡Ã–â”œÃ¢Î“Ã‡Ãœâ”œÃ©â”¬Ã³â”œÃ¢â•žÃ†â”œÃ©â”¬Ã³â”œÃ¢â”¬Ã³â”œÃ³Î“Ã‡Ãœâ”¬Â¼â”œÃ â”¬Ã­â”œÃ¢Î“Ã‡Ãœâ”œÃ©â”¬Â¼â”œÃ¢â•žÃ†â”œÃ³Î“Ã©Â¼â”¬Âªâ”œÃ¢â”¬Ã³â”œÃ³Î“Ã‡Ãœâ”¬Â¼â”œÃ Î“Ã‡Â£ LCD Writing Board | F27: 600 | G27: 7 | H27: 0 | I27: 0 | J27: 0 | K27: NULL | L27: 10.5_ LCD Writing Board (box).jpg | M27: 10.5_ LCD Writing Board 1.jpg | N27: 10.5_ LCD Writing Board 2.jpg | W27: 1500 | X27: 1 | Z27: 2025-06-26T13:32:00.99999999627470925 | AA27: 2025-06-26T13:32:00.99999999627470925 | AB27: 30 | AC27: 2026-01-01T23:59:58.00000016111880300 | AD27: 2026-01-31T23:59:58.99999976623803075
A28: 1070 | B28: 87180e5f-083f-4af2-b7a5-0685fe6c843b | C28: 6975628229772 | D28: 6 Brushes Set WB 5001 6 | E28: 6 Brushes Set WB-5001-6 | F28: 300 | G28: 7 | H28: 0 | I28: 0 | J28: 0 | K28: NULL | L28: 6 Brush Set 1.jpg | M28: 6 Brush Set 2.jpg | W28: 1500 | X28: 1 | Z28: 2025-06-26T13:32:00.99999999627470925 | AA28: 2025-06-26T13:32:00.99999999627470925 | AB28: 30 | AC28: 2026-01-01T23:59:58.00000016111880300 | AD28: 2026-01-31T23:59:58.99999976623803075
A29: 1071 | B29: af7a9fd9-69dc-4848-b6e0-6e1e08a3c865 | C29: 6975628229789 | D29: 12 Brushes Set WB 5001 12 | E29: 12 Brushes Set WB-5001-12 | F29: 420 | G29: 7 | H29: 0 | I29: 0 | J29: 0 | K29: NULL | L29: 12 Brush Set.jpg | M29: 12 Brush Set 2.jpg | W29: 1500 | X29: 1 | Z29: 2025-06-26T13:32:00.99999999627470925 | AA29: 2025-06-26T13:32:00.99999999627470925 | AB29: 29.76 | AC29: 2026-01-01T23:59:58.00000016111880300 | AD29: 2026-01-31T23:59:58.99999976623803075
A30: 1072 | B30: e7418a04-95b1-42db-8c32-2f17475d1df6 | C30: 6975628229758 | D30: 12 Colors Acrylic Paint | E30: 12 Colors Acrylic Paint | F30: 400 | G30: 7 | H30: 0 | I30: 0 | J30: 0 | K30: NULL | L30: 12 Color Acrylic Paint 1.jpg | M30: 12 Color Acrylic Paint 2.jpg | W30: 1500 | X30: 1 | Z30: 2025-06-26T13:32:00.99999999627470925 | AA30: 2025-06-26T13:32:00.99999999627470925 | AB30: 30 | AC30: 2026-01-01T23:59:58.00000016111880300 | AD30: 2026-01-31T23:59:58.99999976623803075
A31: 1076 | B31: 288e854a-d99e-465c-872a-f6a3127f10a9 | C31: 6975628229796 | D31: 18 Colors Acrylic Paint | E31: 18 Colors Acrylic Paint | F31: 630 | G31: 7 | H31: 0 | I31: 0 | J31: 0 | K31: NULL | L31: 18 Color Acrylic Paint 1.jpg | M31: 18 Color Acrylic Paint 2.jpg | W31: 1500 | X31: 1 | Z31: 2025-06-26T13:32:00.99999999627470925 | AA31: 2025-06-26T13:32:00.99999999627470925 | AB31: 30.16 | AC31: 2026-01-01T23:59:58.00000016111880300 | AD31: 2026-01-31T23:59:58.99999976623803075
A32: 1081 | B32: 6793014d-53af-4392-85f5-47305eb44fa5 | C32: 6976693309840 | D32: 24 colors Watercolor Cake Set | E32: 24 colors Watercolor Cake Set | F32: 850 | G32: 7 | H32: 0 | I32: 0 | J32: 0 | K32: NULL | L32: 24 Colors Watercolor Cake set 1.jpg | M32: 24 Colors Watercolor Cake set 2.jpg | W32: 1500 | X32: 1 | Z32: 2025-06-26T13:32:00.99999999627470925 | AA32: 2025-06-26T13:32:00.99999999627470925 | AB32: 30 | AC32: 2026-01-01T23:59:58.00000016111880300 | AD32: 2026-01-31T23:59:58.99999976623803075
A33: 1083 | B33: f765bbaa-7045-4283-843a-1a39fd982e4b | C33: 6976693300106 | D33: 36 Colors Watercolor Acuarela | E33: 37 Colors Watercolor Acuarela | F33: 660 | G33: 7 | H33: 0 | I33: 0 | J33: 0 | K33: NULL | L33: 36 Colour Watercolour.jpg | W33: 1500 | X33: 1 | Z33: 2025-06-26T13:32:00.99999999627470925 | AA33: 2025-06-26T13:32:00.99999999627470925 | AB33: 30 | AC33: 2026-01-01T23:59:58.00000016111880300 | AD33: 2026-01-31T23:59:58.99999976623803075
A34: 1092 | B34: 4ed14066-ceb6-44e6-a460-93ef2bf4cf97 | C34: 6971082815421 | D34: Blue Neutral Pen | E34: Blue Neutral Pen | F34: 100 | G34: 7 | H34: 0 | I34: 0 | J34: 0 | K34: NULL | L34: Blue Neutral Pen.jpg | W34: 1500 | X34: 1 | Z34: 2025-06-26T13:32:00.99999999627470925 | AA34: 2025-06-26T13:32:00.99999999627470925 | AB34: 30 | AC34: 2026-01-01T23:59:58.00000016111880300 | AD34: 2026-01-31T23:59:58.99999976623803075
A35: 1098 | B35: b90e4014-0ab1-48d0-96af-4b21a1a78d66 | C35: 6971082810402 | D35: 12 Colors Watercolor Pen | E35: 12 Colors Watercolor Pen | F35: 290 | G35: 7 | H35: 0 | I35: 0 | J35: 0 | K35: NULL | L35: Colors Water Colors 1.jpg | M35: Colors Water Colors 2.jpg | W35: 1500 | X35: 1 | Z35: 2025-06-26T13:32:00.99999999627470925 | AA35: 2025-06-26T13:32:00.99999999627470925 | AB35: 31.03 | AC35: 2026-01-01T23:59:58.00000016111880300 | AD35: 2026-01-31T23:59:58.99999976623803075
A36: 1100 | B36: bc87edb0-e794-4684-96f2-4358809c8b60 | C36: 6971082812239 | D36: 12 Colors Twin Marker | E36: 12 Colors Twin Marker | F36: 500 | G36: 7 | H36: 0 | I36: 0 | J36: 0 | K36: NULL | L36: Colour Twin Marker (12 colors)1.jpg | M36: Colour Twin Marker (12 colors)2.jpg | W36: 1500 | X36: 1 | Z36: 2025-06-26T13:32:00.99999999627470925 | AA36: 2025-06-26T13:32:00.99999999627470925 | AB36: 30 | AC36: 2026-01-01T23:59:58.00000016111880300 | AD36: 2026-01-31T23:59:58.99999976623803075
A37: 1101 | B37: 833e488c-aaac-4732-9a17-a186222a550b | C37: 6971082816251 | D37: 18 Colors Twin Marker | E37: 18 Colors Twin Marker | F37: 800 | G37: 7 | H37: 0 | I37: 0 | J37: 0 | K37: NULL | L37: Colour Twin Marker (18 colors)1.jpg | M37: Colour Twin Marker (18 colors)2.jpg | W37: 1500 | X37: 1 | Z37: 2025-06-26T13:32:00.99999999627470925 | AA37: 2025-06-26T13:32:00.99999999627470925 | AB37: 30 | AC37: 2026-01-01T23:59:58.00000016111880300 | AD37: 2026-01-31T23:59:58.99999976623803075
A38: 1102 | B38: e7e1cef7-cf5a-4e4c-bb10-ca088fa0cb9a | C38: 6971082818811 | D38: Correction Tape | E38: Correction Tape | F38: 60 | G38: 7 | H38: 0 | I38: 0 | J38: 0 | K38: NULL | L38: Correction Tape (blue).jpg | M38: Correction Tape (green).jpg | N38: Correction Tape (orange).jpg | W38: 1500 | X38: 1 | Z38: 2025-06-26T13:32:00.99999999627470925 | AA38: 2025-06-26T13:32:00.99999999627470925 | AB38: 25 | AC38: 2026-01-01T23:59:58.00000016111880300 | AD38: 2026-01-31T23:59:58.99999976623803075
A39: 1105 | B39: e35d4360-a717-4b4e-9e92-5f8ed844342b | C39: 6971082818811 | D39: CRYSTAL STATIONERY TAPE 12PCS | E39: CRYSTAL STATIONERY TAPE 12PCS | F39: 360 | G39: 7 | H39: 0 | I39: 0 | J39: 0 | K39: NULL | L39: Crystal Stationery Tape 12PCS.jpg | W39: 1500 | X39: 1 | Z39: 2025-06-26T13:32:00.99999999627470925 | AA39: 2025-06-26T13:32:00.99999999627470925 | AB39: 25 | AC39: 2026-01-01T23:59:58.00000016111880300 | AD39: 2026-01-31T23:59:58.99999976623803075
A40: 1106 | B40: f890be06-fd35-4428-8932-81647ee82a14 | C40: 6971082818811 | D40: Weibo Desktop Calculator | E40: Weibo Desktop Calculator | F40: 600 | G40: 7 | H40: 0 | I40: 0 | J40: 0 | K40: NULL | L40: Desktop Calculator 1.jpg | M40: Desktop Calculator 2.jpg | W40: 1500 | X40: 1 | Z40: 2025-06-26T13:32:00.99999999627470925 | AA40: 2025-06-26T13:32:00.99999999627470925 | AB40: 25 | AC40: 2026-01-01T23:59:58.00000016111880300 | AD40: 2026-01-31T23:59:58.99999976623803075
...

Sheet Sheet1
A1: barcode | B1: selling_price
A2: 6920250103143 | B2: 550
A3: 6920250103150 | B3: 420
A4: 6920250103181 | B4: 520
A5: 6920250103358 | B5: 640
A6: 6920250103396 | B6: 800
A7: 6920250103419 | B7: 700
A8: 6920250103532 | B8: 780
A9: 6971082817432 | B9: 200
A10: 6971082817449 | B10: 280
A11: 6971082817456 | B11: 360
A12: 6976693300076 | B12: 320
A13: 6976693300090 | B13: 700
... A110: 6920250103457 | B110: 1020

Sheet Sheet2
A1: BARCODE
A2: 5602023218025 | B2: 250 | C2: =IFERROR(IF(B2 = VLOOKUP(A2, Sheet1!A:B, 2, FALSE), "Match", "Price Mismatch"), "Barcode Not Found") -> Barcode Not Found
A3: 5602023218032 | B3: 150 | C3: =IFERROR(IF(B3 = VLOOKUP(A3, Sheet1!A:B, 2, FALSE), "Match", "Price Mismatch"), "Barcode Not Found") -> Barcode Not Found
A4: 5602023218049 | B4: 180 | C4: =IFERROR(IF(B4 = VLOOKUP(A4, Sheet1!A:B, 2, FALSE), "Match", "Price Mismatch"), "Barcode Not Found") -> Barcode Not Found
A5: 5602023218056 | B5: 200 | C5: =IFERROR(IF(B5 = VLOOKUP(A5, Sheet1!A:B, 2, FALSE), "Match", "Price Mismatch"), "Barcode Not Found") -> Barcode Not Found
A6: 6975628229932 | B6: 200 | C6: =IFERROR(IF(B6 = VLOOKUP(A6, Sheet1!A:B, 2, FALSE), "Match", "Price Mismatch"), "Barcode Not Found") -> Barcode Not Found
A7: 6976693302551 | B7: 300 | C7: =IFERROR(IF(B7 = VLOOKUP(A7, Sheet1!A:B, 2, FALSE), "Match", "Price Mismatch"), "Barcode Not Found") -> Barcode Not Found
A8: 6975628229949 | B8: 240 | C8: =IFERROR(IF(B8 = VLOOKUP(A8, Sheet1!A:B, 2, FALSE), "Match", "Price Mismatch"), "Barcode Not Found") -> Barcode Not Found
A9: 6949832800072 | B9: 200 | C9: =IFERROR(IF(B9 = VLOOKUP(A9, Sheet1!A:B, 2, FALSE), "Match", "Price Mismatch"), "Barcode Not Found") -> Barcode Not Found
A10: 6949832880012 | B10: 200 | C10: =IFERROR(IF(B10 = VLOOKUP(A10, Sheet1!A:B, 2, FALSE), "Match", "Price Mismatch"), "Barcode Not Found") -> Barcode Not Found
A11: 6949832800270 | B11: 200 | C11: =IFERROR(IF(B11 = VLOOKUP(A11, Sheet1!A:B, 2, FALSE), "Match", "Price Mismatch"), "Barcode Not Found") -> Barcode Not Found
A12: 6949832800065 | B12: 200 | C12: =IFERROR(IF(B12 = VLOOKUP(A12, Sheet1!A:B, 2, FALSE), "Match", "Price Mismatch"), "Barcode Not Found") -> Barcode Not Found
A13: 6949832800096 | B13: 200 | C13: =IFERROR(IF(B13 = VLOOKUP(A13, Sheet1!A:B, 2, FALSE), "Match", "Price Mismatch"), "Barcode Not Found") -> Barcode Not Found
... A104: 6973281334543 | B104: 240 | C104: =IFERROR(IF(B104 = VLOOKUP(A104, Sheet1!A:B, 2, FALSE), "Match", "Price Mismatch"), "Barcode Not Found") -> Barcode Not Found
A106: 1
